<?xml version="1.0" ?>
<!-- =================================================================================== -->
<!-- |    This document was autogenerated by xacro from fourth_robot.urdf.xacro        | -->
<!-- |    EDITING THIS FILE BY HAND IS NOT RECOMMENDED                                 | -->
<!-- =================================================================================== -->
<robot name="rs_robot">
  <!-- =============== Link & Joint =============== -->
  <!-- Base -->
  <link name="base_footprint"/>
  <joint name="base_link_joint" type="fixed">
    <origin xyz="0 0 0"/>
    <parent link="base_footprint"/>
    <child link="base_link"/>
  </joint>
  <link name="base_link">
    <visual>
      <geometry>
        <mesh filename="package://robot_description/meshes/DAE/base/base_link.dae"/>
      </geometry>
    </visual>
    <collision>
      <geometry>
        <mesh filename="package://robot_description/meshes/STL/base/base_link.stl"/>
      </geometry>
    </collision>
    <inertial>
      <origin xyz="0 0 0.017"/>
      <mass value="1.2"/>
      <inertia ixx="0.0001873" ixy="0" ixz="0" iyy="0.000055" iyz="0" izz="0.0002283"/>
    </inertial>
  </link>
  <joint name="lidar_base_link_joint" type="fixed">
    <origin xyz="-0.022 0 0.035"/>
    <parent link="base_link"/>
    <child link="lidar_base_link"/>
  </joint>
  <link name="lidar_base_link">
    <visual>
      <geometry>
        <mesh filename="package://robot_description/meshes/DAE/lidar_base/YDlidar_base.dae"/>
      </geometry>
    </visual>
    <collision>
      <geometry>
        <mesh filename="package://robot_description/meshes/STL/lidar_base/YDlidar_base.stl"/>
      </geometry>
    </collision>
    <inertial>
      <origin xyz="0 0 0.017"/>
      <mass value="0.2"/>
      <inertia ixx="0.0000873" ixy="0" ixz="0" iyy="0.000005" iyz="0" izz="0.0000283"/>
    </inertial>
  </link>
  <joint name="lidar_head_joint" type="continuous">
    <origin xyz="0.022 0 0.0"/>
    <parent link="lidar_base_link"/>
    <child link="lidar_head_link"/>
    <limit effort="1.5" velocity="20"/>
    <axis xyz="0 0 1"/>
  </joint>
  <link name="lidar_head_link">
    <visual>
      <geometry>
        <mesh filename="package://robot_description/meshes/DAE/lidar_head/YDlidar_head.dae"/>
      </geometry>
    </visual>
    <collision>
      <geometry>
        <mesh filename="package://robot_description/meshes/STL/lidar_head/YDlidar_head.stl"/>
      </geometry>
    </collision>
    <inertial>
      <origin xyz="0.0 0 0"/>
      <mass value="0.05"/>
      <inertia ixx="0.00001" ixy="0" ixz="0" iyy="0.000018" iyz="0" izz="0.00001"/>
    </inertial>
  </link>
  <joint name="front_lrf_joint" type="fixed">
    <origin xyz="0 0 0.083"/>
    <parent link="base_link"/>
    <child link="front_lrf_link"/>
  </joint>
  <link name="front_lrf_link">
	</link>
  <link name="lrf_link"/>
  <joint name="lrf_link_joint" type="fixed">
    <parent link="base_link"/>
    <child link="lrf_link"/>
    <origin xyz="0 0 0.01"/>
  </joint>
  <joint name="front_right_steering_joint" type="revolute">
    <origin xyz="0.077 -0.031 -0.004"/>
    <parent link="base_link"/>
    <child link="front_right_steering_link"/>
    <limit effort="5" lower="-2.1" upper="2.1" velocity="6.28"/>
    <axis xyz="0 0 1"/>
  </joint>
  <link name="front_right_steering_link">
    <visual>
      <geometry>
        <mesh filename="package://robot_description/meshes/DAE/suspension/front_right_link.dae"/>
      </geometry>
    </visual>
    <collision>
      <geometry>
        <mesh filename="package://robot_description/meshes/STL/suspension/sus_link.stl"/>
      </geometry>
    </collision>
    <inertial>
      <origin xyz="0 0 -0.02"/>
      <mass value="0.15"/>
      <inertia ixx="0.00001" ixy="0" ixz="0" iyy="0.00001" iyz="0" izz="0.000004"/>
    </inertial>
  </link>
  <joint name="front_left_steering_joint" type="revolute">
    <origin xyz="0.077 0.031 -0.004"/>
    <parent link="base_link"/>
    <child link="front_left_steering_link"/>
    <limit effort="5" lower="-2.1" upper="2.1" velocity="6.28"/>
    <axis xyz="0 0 1"/>
  </joint>
  <link name="front_left_steering_link">
    <visual>
      <geometry>
        <mesh filename="package://robot_description/meshes/DAE/suspension/front_left_link.dae"/>
      </geometry>
    </visual>
    <collision>
      <geometry>
        <mesh filename="package://robot_description/meshes/STL/suspension/sus_link.stl"/>
      </geometry>
    </collision>
    <inertial>
      <origin xyz="0 0 -0.02"/>
      <mass value="0.15"/>
      <inertia ixx="0.00001" ixy="0" ixz="0" iyy="0.00001" iyz="0" izz="0.000004"/>
    </inertial>
  </link>
  <joint name="rear_right_steering_joint" type="revolute">
    <origin xyz="-0.077 -0.031 -0.004"/>
    <parent link="base_link"/>
    <child link="rear_right_steering_link"/>
    <limit effort="5" lower="-2.1" upper="2.1" velocity="6.28"/>
    <axis xyz="0 0 1"/>
  </joint>
  <link name="rear_right_steering_link">
    <visual>
      <geometry>
        <mesh filename="package://robot_description/meshes/DAE/suspension/rear_right_link.dae"/>
      </geometry>
    </visual>
    <collision>
      <geometry>
        <mesh filename="package://robot_description/meshes/STL/suspension/sus_link.stl"/>
      </geometry>
    </collision>
    <inertial>
      <origin xyz="0 0 -0.02"/>
      <mass value="0.15"/>
      <inertia ixx="0.00001" ixy="0" ixz="0" iyy="0.00001" iyz="0" izz="0.000004"/>
    </inertial>
  </link>
  <joint name="rear_left_steering_joint" type="revolute">
    <origin xyz="-0.077 0.031 -0.004"/>
    <parent link="base_link"/>
    <child link="rear_left_steering_link"/>
    <limit effort="5" lower="-2.1" upper="2.1" velocity="6.28"/>
    <axis xyz="0 0 1"/>
  </joint>
  <link name="rear_left_steering_link">
    <visual>
      <geometry>
        <mesh filename="package://robot_description/meshes/DAE/suspension/rear_left_link.dae"/>
      </geometry>
    </visual>
    <collision>
      <geometry>
        <mesh filename="package://robot_description/meshes/STL/suspension/sus_link.stl"/>
      </geometry>
    </collision>
    <inertial>
      <origin xyz="0 0 -0.02"/>
      <mass value="0.15"/>
      <inertia ixx="0.00001" ixy="0" ixz="0" iyy="0.00001" iyz="0" izz="0.000004"/>
    </inertial>
  </link>
  <joint name="ffr_wheel_joint" type="continuous">
    <origin xyz="0 -0.021 -0.025"/>
    <parent link="front_right_steering_link"/>
    <child link="ffr_wheel_link"/>
    <limit effort="1.5" velocity="20"/>
    <axis xyz="0 1 0"/>
  </joint>
  <link name="ffr_wheel_link">
    <visual>
      <geometry>
        <mesh filename="package://robot_description/meshes/DAE/wheel/wheel_link.dae"/>
      </geometry>
    </visual>
    <collision>
      <geometry>
        <mesh filename="package://robot_description/meshes/STL/wheel/robot_wheel.stl"/>
      </geometry>
    </collision>
    <inertial>
      <origin xyz="0.0 -0.007 -0.0"/>
      <mass value="0.05"/>
      <inertia ixx="0.00001" ixy="0" ixz="0" iyy="0.000018" iyz="0" izz="0.00001"/>
    </inertial>
  </link>
  <joint name="ffl_wheel_joint" type="continuous">
    <origin rpy="0 0 3.14159274" xyz="0 0.021 -0.025"/>
    <parent link="front_left_steering_link"/>
    <child link="ffl_wheel_link"/>
    <limit effort="1.5" velocity="20"/>
    <axis xyz="0 -1 0"/>
  </joint>
  <link name="ffl_wheel_link">
    <visual>
      <geometry>
        <mesh filename="package://robot_description/meshes/DAE/wheel/wheel_link.dae"/>
      </geometry>
    </visual>
    <collision>
      <geometry>
        <mesh filename="package://robot_description/meshes/STL/wheel/robot_wheel.stl"/>
      </geometry>
    </collision>
    <inertial>
      <origin xyz="0.0 -0.007 -0.0"/>
      <mass value="0.05"/>
      <inertia ixx="0.00001" ixy="0" ixz="0" iyy="0.000018" iyz="0" izz="0.00001"/>
    </inertial>
  </link>
  <joint name="rfr_wheel_joint" type="continuous">
    <origin xyz="0 -0.021 -0.025"/>
    <parent link="rear_right_steering_link"/>
    <child link="rfr_wheel_link"/>
    <limit effort="1.5" velocity="20"/>
    <axis xyz="0 1 0"/>
  </joint>
  <link name="rfr_wheel_link">
    <visual>
      <geometry>
        <mesh filename="package://robot_description/meshes/DAE/wheel/wheel_link.dae"/>
      </geometry>
    </visual>
    <collision>
      <geometry>
        <mesh filename="package://robot_description/meshes/STL/wheel/robot_wheel.stl"/>
      </geometry>
    </collision>
    <inertial>
      <origin xyz="0.0 -0.007 -0.0"/>
      <mass value="0.05"/>
      <inertia ixx="0.00001" ixy="0" ixz="0" iyy="0.000018" iyz="0" izz="0.00001"/>
    </inertial>
  </link>
  <joint name="rfl_wheel_joint" type="continuous">
    <origin rpy="0 0 3.14159274" xyz="0 0.021 -0.025"/>
    <parent link="rear_left_steering_link"/>
    <child link="rfl_wheel_link"/>
    <limit effort="1.5" velocity="20"/>
    <axis xyz="0 -1 0"/>
  </joint>
  <link name="rfl_wheel_link">
    <visual>
      <geometry>
        <mesh filename="package://robot_description/meshes/DAE/wheel/wheel_link.dae"/>
      </geometry>
    </visual>
    <collision>
      <geometry>
        <mesh filename="package://robot_description/meshes/STL/wheel/robot_wheel.stl"/>
      </geometry>
    </collision>
    <inertial>
      <origin xyz="0.0 -0.007 -0.0"/>
      <mass value="0.05"/>
      <inertia ixx="0.00001" ixy="0" ixz="0" iyy="0.000018" iyz="0" izz="0.00001"/>
    </inertial>
  </link>

  <ros2_control name="GazeboSystem" type="system">
    <hardware>
      <plugin>gazebo_ros2_control/GazeboSystem</plugin>
    </hardware>
    
    <joint name="ffl_wheel_joint">
      <command_interface name="velocity">
        <param name="min">-3.14</param>
        <param name="max">3.14</param>
      </command_interface>
      <state_interface name="velocity"/>
      <state_interface name="effort"/>
    </joint>

    <joint name="ffr_wheel_joint">
      <command_interface name="velocity">
        <param name="min">-3.14</param>
        <param name="max">3.14</param>
      </command_interface>
      <state_interface name="velocity"/>
      <state_interface name="effort"/>
    </joint>

    <joint name="rfl_wheel_joint">
      <command_interface name="velocity">
        <param name="min">-3.14</param>
        <param name="max">3.14</param>
      </command_interface>
      <state_interface name="velocity"/>
      <state_interface name="effort"/>
    </joint>

    <joint name="rfr_wheel_joint">
      <command_interface name="velocity">
        <param name="min">-3.14</param>
        <param name="max">3.14</param>
      </command_interface>
      <state_interface name="velocity"/>
      <state_interface name="effort"/>
    </joint>

    <joint name="front_left_steering_joint">
      <command_interface name="position">
        <param name="min">-3.14</param>
        <param name="max">3.14</param>
      </command_interface>
      <state_interface name="position"/>
      <state_interface name="velocity"/>
      <state_interface name="effort"/>
    </joint>

    <joint name="front_right_steering_joint">
      <command_interface name="position">
        <param name="min">-3.14</param>
        <param name="max">3.14</param>
      </command_interface>
      <state_interface name="position"/>
      <state_interface name="velocity"/>
      <state_interface name="effort"/>
    </joint>

    <joint name="rear_left_steering_joint">
      <command_interface name="position">
        <param name="min">-3.14</param>
        <param name="max">3.14</param>
      </command_interface>
      <state_interface name="position"/>
      <state_interface name="velocity"/>
      <state_interface name="effort"/>
    </joint>

    <joint name="rear_right_steering_joint">
      <command_interface name="position">
        <param name="min">-3.14</param>
        <param name="max">3.14</param>
      </command_interface>
      <state_interface name="position"/>
      <state_interface name="velocity"/>
      <state_interface name="effort"/>
    </joint>
  </ros2_control>

    <plugin name="gazebo_ros2_control" filename="libgazebo_ros2_control.so">
      <parameters>$(find gazebo_simulation)/config/controllers.yaml</parameters>
    </plugin>

  <!-- =============== Gazebo =============== -->
  <gazebo reference="base_link">
    <selfCollide>false</selfCollide>
    <mu1 value="0.05"/>
    <mu2 value="0.05"/>
  </gazebo>
  <gazebo reference="lidar_base_link">
    <selfCollide>false</selfCollide>
    <mu1 value="0.05"/>
    <mu2 value="0.05"/>
  </gazebo>
  <gazebo reference="lidar_head_link">
    <selfCollide>false</selfCollide>
    <mu1 value="0.05"/>
    <mu2 value="0.05"/>
  </gazebo>
  <gazebo reference="fr_wheel_link">
    <selfCollide>false</selfCollide>
    <mu1 value="1.2"/>
    <mu2 value="1.2"/>
  </gazebo>
  <gazebo reference="fl_wheel_link">
    <selfCollide>false</selfCollide>
    <mu1 value="1.2"/>
    <mu2 value="1.2"/>
  </gazebo>
  <gazebo reference="rr_wheel_link">
    <selfCollide>false</selfCollide>
    <mu1 value="1.2"/>
    <mu2 value="1.2"/>
  </gazebo>
  <gazebo reference="rl_wheel_link">
    <selfCollide>false</selfCollide>
    <mu1 value="1.2"/>
    <mu2 value="1.2"/>
  </gazebo>
  <gazebo reference="front_right_steering_link">
    <selfCollide>false</selfCollide>
    <mu1 value="0.05"/>
    <mu2 value="0.05"/>
  </gazebo>
  <gazebo reference="front_left_steering_link">
    <selfCollide>false</selfCollide>
    <mu1 value="0.05"/>
    <mu2 value="0.05"/>
  </gazebo>
  <gazebo reference="rear_right_steering_link">
    <selfCollide>false</selfCollide>
    <mu1 value="0.05"/>
    <mu2 value="0.05"/>
  </gazebo>
  <gazebo reference="rear_left_steering_link">
    <selfCollide>false</selfCollide>
    <mu1 value="0.05"/>
    <mu2 value="0.05"/>
  </gazebo>
</robot>

